2020-10-31 14:51:01,864:DEBUG:certbot._internal.main:certbot version: 1.9.0
2020-10-31 14:51:01,865:DEBUG:certbot._internal.main:Arguments: ['--webroot', '--webroot-path=/usr/share/nginx/html/letsencrypt', '--email', 'a@somin.tech', '--agree-tos', '--no-eff-email', '-d', 'artifactory.somin.tech']
2020-10-31 14:51:01,865:DEBUG:certbot._internal.main:Discovered plugins: PluginsRegistry(PluginEntryPoint#manual,PluginEntryPoint#null,PluginEntryPoint#standalone,PluginEntryPoint#webroot)
2020-10-31 14:51:01,927:DEBUG:certbot._internal.log:Root logging level set at 20
2020-10-31 14:51:01,928:INFO:certbot._internal.log:Saving debug log to /var/log/letsencrypt/letsencrypt.log
2020-10-31 14:51:01,929:DEBUG:certbot._internal.plugins.selection:Requested authenticator webroot and installer None
2020-10-31 14:51:01,934:DEBUG:certbot._internal.plugins.selection:Single candidate plugin: * webroot
Description: Place files in webroot directory
Interfaces: IAuthenticator, IPlugin
Entry point: webroot = certbot._internal.plugins.webroot:Authenticator
Initialized: <certbot._internal.plugins.webroot.Authenticator object at 0x7f49aa903c70>
Prep: True
2020-10-31 14:51:01,934:DEBUG:certbot._internal.plugins.selection:Selected authenticator <certbot._internal.plugins.webroot.Authenticator object at 0x7f49aa903c70> and installer None
2020-10-31 14:51:01,934:INFO:certbot._internal.plugins.selection:Plugins selected: Authenticator webroot, Installer None
2020-10-31 14:51:01,939:DEBUG:certbot._internal.main:Picked account: <Account(RegistrationResource(body=Registration(key=None, contact=(), agreement=None, status=None, terms_of_service_agreed=None, only_return_existing=None, external_account_binding=None), uri='https://acme-v02.api.letsencrypt.org/acme/acct/100909398', new_authzr_uri=None, terms_of_service=None), c8e659eecd9803781ab66ba6a1b3e5bb, Meta(creation_dt=datetime.datetime(2020, 10, 31, 13, 51, 52, tzinfo=<UTC>), creation_host='4ecf338a42c7', register_to_eff=None))>
2020-10-31 14:51:01,940:DEBUG:acme.client:Sending GET request to https://acme-v02.api.letsencrypt.org/directory.
2020-10-31 14:51:01,943:DEBUG:urllib3.connectionpool:Starting new HTTPS connection (1): acme-v02.api.letsencrypt.org:443
2020-10-31 14:51:02,563:DEBUG:urllib3.connectionpool:https://acme-v02.api.letsencrypt.org:443 "GET /directory HTTP/1.1" 200 658
2020-10-31 14:51:02,564:DEBUG:acme.client:Received response:
HTTP 200
Server: nginx
Date: Sat, 31 Oct 2020 14:51:02 GMT
Content-Type: application/json
Content-Length: 658
Connection: keep-alive
Cache-Control: public, max-age=0, no-cache
X-Frame-Options: DENY
Strict-Transport-Security: max-age=604800

{
  "2KV5y9K5fWk": "https://community.letsencrypt.org/t/adding-random-entries-to-the-directory/33417",
  "keyChange": "https://acme-v02.api.letsencrypt.org/acme/key-change",
  "meta": {
    "caaIdentities": [
      "letsencrypt.org"
    ],
    "termsOfService": "https://letsencrypt.org/documents/LE-SA-v1.2-November-15-2017.pdf",
    "website": "https://letsencrypt.org"
  },
  "newAccount": "https://acme-v02.api.letsencrypt.org/acme/new-acct",
  "newNonce": "https://acme-v02.api.letsencrypt.org/acme/new-nonce",
  "newOrder": "https://acme-v02.api.letsencrypt.org/acme/new-order",
  "revokeCert": "https://acme-v02.api.letsencrypt.org/acme/revoke-cert"
}
2020-10-31 14:51:02,572:DEBUG:urllib3.connectionpool:Starting new HTTP connection (1): ocsp.int-x3.letsencrypt.org:80
2020-10-31 14:51:02,601:DEBUG:urllib3.connectionpool:http://ocsp.int-x3.letsencrypt.org:80 "POST / HTTP/1.1" 200 527
2020-10-31 14:51:02,602:DEBUG:certbot.ocsp:OCSP response for certificate /etc/letsencrypt/archive/artifactory.somin.tech/cert1.pem is signed by the certificate's issuer.
2020-10-31 14:51:02,606:DEBUG:certbot.ocsp:OCSP certificate status for /etc/letsencrypt/archive/artifactory.somin.tech/cert1.pem is: OCSPCertStatus.GOOD
2020-10-31 14:51:02,612:INFO:certbot._internal.renewal:Cert not yet due for renewal
2020-10-31 14:51:02,613:DEBUG:certbot._internal.log:Exiting abnormally:
Traceback (most recent call last):
  File "/usr/local/bin/certbot", line 11, in <module>
    load_entry_point('certbot', 'console_scripts', 'certbot')()
  File "/opt/certbot/src/certbot/certbot/main.py", line 15, in main
    return internal_main.main(cli_args)
  File "/opt/certbot/src/certbot/certbot/_internal/main.py", line 1362, in main
    return config.func(config, plugins)
  File "/opt/certbot/src/certbot/certbot/_internal/main.py", line 1236, in certonly
    should_get_cert, lineage = _find_cert(config, domains, certname)
  File "/opt/certbot/src/certbot/certbot/_internal/main.py", line 287, in _find_cert
    action, lineage = _find_lineage_for_domains_and_certname(config, domains, certname)
  File "/opt/certbot/src/certbot/certbot/_internal/main.py", line 314, in _find_lineage_for_domains_and_certname
    return _find_lineage_for_domains(config, domains)
  File "/opt/certbot/src/certbot/certbot/_internal/main.py", line 264, in _find_lineage_for_domains
    return _handle_identical_cert_request(config, ident_names_cert)
  File "/opt/certbot/src/certbot/certbot/_internal/main.py", line 216, in _handle_identical_cert_request
    response = display.menu(question, choices,
  File "/opt/certbot/src/certbot/certbot/display/util.py", line 153, in menu
    code, selection = self._get_valid_int_ans(len(choices))
  File "/opt/certbot/src/certbot/certbot/display/util.py", line 411, in _get_valid_int_ans
    ans = input_with_timeout(input_msg)
  File "/opt/certbot/src/certbot/certbot/display/util.py", line 85, in input_with_timeout
    raise EOFError
EOFError
2020-10-31 14:51:02,615:ERROR:certbot._internal.log:An unexpected error occurred:
2020-10-31 14:51:02,615:ERROR:certbot._internal.log:EOFError
